<?xml version="1.0" ?>
<sdf version="1.7">
  <model name="becard_base">
    <static>false</static>

    <!-- ================= BASE LINK ================= -->
    <link name="base_link">
      <pose>0 0 0 0 0 0</pose>
      <inertial>
        <pose>0.018587038207977344 0.010610111030428002 0.007278390231634997 0 0 0</pose>
        <mass>3.577022367393264</mass>
        <inertia>
          <ixx>0.019819</ixx>
          <iyy>0.026993</iyy>
          <izz>0.020812</izz>
          <ixy>0.000408</ixy>
          <iyz>0.0</iyz>
          <ixz>1e-06</ixz>
        </inertia>
      </inertial>

      <visual name="base_link_visual">
        <pose>0 0 0 0 0 0</pose>
        <geometry>
          <mesh>
            <uri>model://becard_base/meshes/base_link.stl</uri>
            <scale>0.001 0.001 0.001</scale>
          </mesh>
        </geometry>
        <material>
          <script>
            <uri>file://media/materials/scripts/gazebo.material</uri>
            <name>Gazebo/Silver</name>
          </script>
        </material>
      </visual>

      <collision name="base_link_collision">
        <pose>0 0 0 0 0 0</pose>
        <geometry>
          <mesh>
            <uri>model://becard_base/meshes/base_link.stl</uri>
            <scale>0.001 0.001 0.001</scale>
          </mesh>
        </geometry>
      </collision>

       <sensor name="air_pressure_sensor" type="air_pressure">
        <gz_frame_id>base_link</gz_frame_id>
        <always_on>1</always_on>
        <update_rate>50</update_rate>
        <air_pressure>
          <!-- Noise modeled after BMP390 -->
          <pressure>
            <noise type="gaussian">
              <mean>0</mean>
              <stddev>3</stddev>
            </noise>
          </pressure>
        </air_pressure>
      </sensor>
      <sensor name="magnetometer_sensor" type="magnetometer">
        <gz_frame_id>base_link</gz_frame_id>
        <always_on>1</always_on>
        <update_rate>100</update_rate>
        <magnetometer>
          <!-- TODO: update to fix units and coordinate system when we move past Harmonic -->
          <!-- See https://github.com/gazebosim/gz-sim/pull/2460 -->
          <!-- 3mgauss RMS: NOTE: noise is in tesla but sensor reports data in gauss -->
          <!-- Noise modeled after IIS2MDC -->
          <x>
            <noise type="gaussian">
              <stddev>0.0001</stddev>
            </noise>
          </x>
          <y>
            <noise type="gaussian">
              <stddev>0.0001</stddev>
            </noise>
          </y>
          <z>
            <noise type="gaussian">
              <stddev>0.0001</stddev>
            </noise>
          </z>
        </magnetometer>
      </sensor>
      <sensor name="imu_sensor" type="imu">
        <gz_frame_id>base_link</gz_frame_id>
        <always_on>1</always_on>
        <update_rate>250</update_rate>
        <imu>
          <angular_velocity>
            <!-- Noise modeled after IIM42653 -->
            <!-- 0.05 deg/s converted to rad/s -->
            <x>
              <noise type="gaussian">
                <mean>0.0</mean>
                <stddev>0.0008726646</stddev>
              </noise>
            </x>
            <y>
              <noise type="gaussian">
                <mean>0.0</mean>
                <stddev>0.0008726646</stddev>
              </noise>
            </y>
            <z>
              <noise type="gaussian">
                <mean>0.0</mean>
                <stddev>0.0008726646</stddev>
              </noise>
            </z>
          </angular_velocity>
          <linear_acceleration>
            <!-- Noise modeled after IIM42653 -->
            <!-- X & Y axis: 0.65 mg-rms converted to m/ss -->
            <x>
              <noise type="gaussian">
                <mean>0.0</mean>
                <stddev>0.00637</stddev>
              </noise>
            </x>
            <y>
              <noise type="gaussian">
                <mean>0.0</mean>
                <stddev>0.00637</stddev>
              </noise>
            </y>
            <!-- Z axis: 0.70 mg-rms converted to m/ss-->
            <z>
              <noise type="gaussian">
                <mean>0.0</mean>
                <stddev>0.00686</stddev>
              </noise>
            </z>
          </linear_acceleration>
        </imu>
      </sensor>
      <sensor name="navsat_sensor" type="navsat">
        <gz_frame_id>base_link</gz_frame_id>
        <always_on>1</always_on>
        <update_rate>30</update_rate>
      </sensor>

    </link>

    <!-- ================= ROTOR 1 ================= -->
    <link name="wirnik_v4_1">
      <pose>0 0 0 0 0 0</pose>
      <inertial>
        <pose>0 0 0 0 0 0</pose>
        <mass>0.009618504415317076</mass>
        <inertia>
          <ixx>3.1e-05</ixx>
          <iyy>3.1e-05</iyy>
          <izz>0</izz>
        </inertia>
      </inertial>

      <visual name="wirnik_v4_1_visual">
        <pose>0 0 0 0 0 0</pose>
        <geometry>
          <mesh>
            <uri>model://becard_base/meshes/wirnik_v4_1.stl</uri>
            <scale>0.001 0.001 0.001</scale>
          </mesh>
        </geometry>
      </visual>

      <collision name="wirnik_v4_1_collision">
        <pose>0 0 0 0 0 0</pose>
        <geometry>
          <mesh>
            <uri>model://becard_base/meshes/wirnik_v4_1.stl</uri>
            <scale>0.001 0.001 0.001</scale>
          </mesh>
        </geometry>
      </collision>
    </link>

    <!-- ================= ROTOR 2 ================= -->
    <link name="wirnik_v4__1__1">
      <pose>0 0 0 0 0 0</pose>
      <inertial>
        <pose>0 0 0 0 0 0</pose>
        <mass>0.009618504415317076</mass>
        <inertia>
          <ixx>3.1e-05</ixx>
          <iyy>3.1e-05</iyy>
          <izz>0</izz>
        </inertia>
      </inertial>

      <visual name="wirnik_v4__1__1_visual">
        <pose>0 0 0 0 0 0</pose>
        <geometry>
          <mesh>
            <uri>model://becard_base/meshes/wirnik_v4__1__1.stl</uri>
            <scale>0.001 0.001 0.001</scale>
          </mesh>
        </geometry>
      </visual>

      <collision name="wirnik_v4__1__1_collision">
        <pose>0 0 0 0 0 0</pose>
        <geometry>
          <mesh>
            <uri>model://becard_base/meshes/wirnik_v4__1__1.stl</uri>
            <scale>0.001 0.001 0.001</scale>
          </mesh>
        </geometry>
      </collision>
    </link>

    <!-- ================= ROTOR 3 ================= -->
    <link name="wirnik_v4__2__1">
      <pose>0 0 0 0 0 0</pose>
      <inertial>
        <pose>0 0 0 0 0 0</pose>
        <mass>0.009618504415317076</mass>
        <inertia>
          <ixx>3.1e-05</ixx>
          <iyy>3.1e-05</iyy>
          <izz>0</izz>
        </inertia>
      </inertial>

      <visual name="wirnik_v4__2__1_visual">
        <pose>0 0 0 0 0 0</pose>
        <geometry>
          <mesh>
            <uri>model://becard_base/meshes/wirnik_v4__2__1.stl</uri>
            <scale>0.001 0.001 0.001</scale>
          </mesh>
        </geometry>
      </visual>

      <collision name="wirnik_v4__2__1_collision">
        <pose>0 0 0 0 0 0</pose>
        <geometry>
          <mesh>
            <uri>model://becard_base/meshes/wirnik_v4__2__1.stl</uri>
            <scale>0.001 0.001 0.001</scale>
          </mesh>
        </geometry>
      </collision>
    </link>

    <!-- ================= ROTOR 4 ================= -->
    <link name="wirnik_v4__3__1">
      <pose>0 0 0 0 0 0</pose>
      <inertial>
        <pose>0 0 0 0 0 0</pose>
        <mass>0.009618504415317076</mass>
        <inertia>
          <ixx>3.1e-05</ixx>
          <iyy>3.1e-05</iyy>
          <izz>0</izz>
        </inertia>
      </inertial>

      <visual name="wirnik_v4__3__1_visual">
        <pose>0 0 0 0 0 0</pose>
        <geometry>
          <mesh>
            <uri>model://becard_base/meshes/wirnik_v4__3__1.stl</uri>
            <scale>0.001 0.001 0.001</scale>
          </mesh>
        </geometry>
      </visual>

      <collision name="wirnik_v4__3__1_collision">
        <pose>0 0 0 0 0 0</pose>
        <geometry>
          <mesh>
            <uri>model://becard_base/meshes/wirnik_v4__3__1.stl</uri>
            <scale>0.001 0.001 0.001</scale>
          </mesh>
        </geometry>
      </collision>
    </link>

    <!-- ================= JOINTS ================= -->
    <joint name="wirnik1" type="continuous">
      <parent>base_link</parent>
      <child>wirnik_v4_1</child>
      <pose>-0.193675 0.023408 0.216695 0 0 0</pose>
      <axis>
        <xyz>-0 1 0</xyz>
      </axis>
    </joint>

    <joint name="wirnik2" type="continuous">
      <parent>base_link</parent>
      <child>wirnik_v4__1__1</child>
      <pose>-0.193675 0.023408 -0.202143 0 0 0</pose>
      <axis>
        <xyz>-0 1 0</xyz>
      </axis>
    </joint>

    <joint name="wirnik3" type="continuous">
      <parent>base_link</parent>
      <child>wirnik_v4__2__1</child>
      <pose>0.225163 0.023408 0.216695 0 0 0</pose>
      <axis>
        <xyz>0 1 0</xyz>
      </axis>
    </joint>

    <joint name="wirnik4" type="continuous">
      <parent>base_link</parent>
      <child>wirnik_v4__3__1</child>
      <pose>0.225163 0.023408 -0.202143 0 0 0</pose>
      <axis>
        <xyz>-0 1 0</xyz>
      </axis>
    </joint>

  </model>
</sdf>
